<?xml version="1.0" ?>
<robot xmlns:xacro="http://www.ros.org/wiki/xacro">

  <xacro:include filename="$(find phantomx_description)/urdf/phantomx.ignition.xacro"/>
  
  <xacro:property name="connect_offset" value="0.02633" />
  <xacro:property name="thigh_offset_y" value="-0.0645" />
  <xacro:property name="thigh_offset_z" value="-0.0145" />

  <xacro:property name="prefix_stl" value="file://$(find phantomx_description)/meshes"/>

  <xacro:macro name="phantomx" params="parent *origin">
    
    <joint name="j_phantomx_attachment" type="fixed">
      <parent link="${parent}"/>
      <child link="MP_BODY"/>
      <xacro:insert_block name="origin" />
    </joint>

    <link name="MP_BODY">
      <inertial>
        <origin xyz="0 0 0" />
        <mass value="0.97559947"/>
        <inertia ixx="3.1081800"  ixy="-0.25460189"  ixz="2.0318174" iyy="6.3787776" iyz="0.16417863" izz="5.3316425" />
      </inertial>
      <visual>
        <!--origin xyz="-0.0235 0 -0.03525" rpy="0 0 0" /-->
        <origin xyz="0 0 0" rpy="0 0 0" />
        <geometry>
          <!--box size="0.102 0.109 0.106" /-->
          <mesh filename="${prefix_stl}/body.STL"  scale="1 1 1"/>
        </geometry>
        <material name="Grey">
          <color rgba="0.20 0.20 0.20 1.0"/>
        </material>
      </visual>
      <collision>
        <origin xyz="0 0 0" rpy="0 0 0" />
        <geometry>
          <mesh filename="${prefix_stl}/body_coll.STL"  scale="1 1 1"/>
        </geometry>
      </collision>
    </link>
    
    <xacro:leg_l xyz="0.1248 -0.06164  0.001116"  rpy="0 4.7123 0.7853981633974483" suffix="rf"/>
    <xacro:leg_l xyz="0 -0.1034  0.001116"  rpy="0 4.7123 0" suffix="rm"/>
    <xacro:leg_l xyz="-0.1248 -0.06164  0.001116"  rpy="0 4.7123 -0.7853981633974483" suffix="rr"/>

    <xacro:leg_l xyz="0.1248 0.06164  0.001116"  rpy="0 4.7123 2.356194490192345" suffix="lf"/>
    <xacro:leg_l xyz="0 0.1034  0.001116"  rpy="0 4.7123 3.14159" suffix="lm"/>
    <xacro:leg_l xyz="-0.1248 0.06164  0.001116"  rpy="0 4.7123 3.9269908169872414" suffix="lr"/>
    
    <xacro:phantomx_ign />

  </xacro:macro>

  <xacro:macro name="leg_l" params="xyz rpy suffix">

    <link name="c1_${suffix}">
      <inertial>
        <origin xyz="0 -${connect_offset} 0" rpy="0 0 0"  />
        <mass value="0.024357719"/>
        <inertia ixx="${(1/12)*(0.024357719)*((0.045)*(0.045) + (0.022)*(0.022))}"  ixy="0"  ixz="0" iyy="${(1/12)*(0.024357719)*((0.022)*(0.022) + (0.0325)*(0.0325))}" iyz="0" izz="${(1/12)*(0.024357719)*((0.0325)*(0.0325) + (0.045)*(0.045))}"/>
      </inertial>
      <visual>
        <origin xyz="0 -0.0252 0" rpy="0 0 0"  />
        <geometry>
          <!--box size="0.045 0.022 0.0325" /-->
          <mesh filename="${prefix_stl}/connect.STL"  scale="1 1 1"/>
        </geometry>
        <material name="Grey">
          <color rgba="0.20 0.20 0.20 1.0"/>
        </material>
      </visual>
      <collision>
        <origin xyz="0 -${connect_offset} 0" rpy="0 0 0"  />
        <geometry>
          <mesh filename="${prefix_stl}/connect_coll.STL"  scale="1 1 1"/>
        </geometry>
      </collision>
    </link>
    
    <link name="c2_${suffix}">
      <inertial>
        <origin xyz="0 -${connect_offset} 0" rpy="0 0 0"  />
        <mass value="0.024357719"/>
        <inertia ixx="${(1/12)*(0.024357719)*((0.045)*(0.045) + (0.022)*(0.022))}"  ixy="0"  ixz="0" iyy="${(1/12)*(0.024357719)*((0.022)*(0.022) + (0.0325)*(0.0325))}" iyz="0" izz="${(1/12)*(0.024357719)*((0.0325)*(0.0325) + (0.045)*(0.045))}"/>
      </inertial>
      <visual>
        <origin xyz="0 -0.0252 0" rpy="0 0 0"  />
        <geometry>
          <!--box size="0.045 0.022 0.0325" /-->
          <mesh filename="${prefix_stl}/connect.STL"  scale="1 1 1"/>
        </geometry>
        <material name="Grey">
          <color rgba="0.20 0.20 0.20 1.0"/>
        </material>
      </visual>
      <collision>
        <origin xyz="0 -${connect_offset} 0" rpy="0 0 0"  />
        <geometry>
          <mesh filename="${prefix_stl}/connect_coll.STL"  scale="1 1 1"/>
        </geometry>
      </collision>
    </link>

    <link name="thigh_${suffix}">
      <inertial>
        <origin xyz="0 0 0" rpy="0 0 0"  />
        <mass value="0.024357719"/>
        <inertia ixx="${(1/12)*(0.024357719)*((0.045)*(0.045) + (0.022)*(0.022))}"  ixy="0"  ixz="0" iyy="${(1/12)*(0.024357719)*((0.022)*(0.022) + (0.0325)*(0.0325))}" iyz="0" izz="${(1/12)*(0.024357719)*((0.0325)*(0.0325) + (0.045)*(0.045))}"/>
      </inertial>
      <visual>
        <origin xyz="0 0 0" rpy="0 0 0"  />
        <geometry>
          <!--box size="0.045 0.022 0.0325" /-->
          <mesh filename="${prefix_stl}/thigh_l.STL"  scale="1 1 1"/>
        </geometry>
        <material name="Grey">
          <color rgba="0.20 0.20 0.20 1.0"/>
        </material>
      </visual>
      <collision>
        <origin xyz="0 0 0" rpy="0 0 0"  />
        <geometry>
          <mesh filename="${prefix_stl}/thigh_l_coll.STL"  scale="1 1 1"/>
        </geometry>
      </collision>
    </link>

    <link name="tibia_${suffix}">
      <inertial>
        <origin xyz="0 0 0" rpy="0 0 0"  />
        <mass value="0.024357719"/>
        <inertia ixx="${(1/12)*(0.024357719)*((0.045)*(0.045) + (0.022)*(0.022))}"  ixy="0"  ixz="0" iyy="${(1/12)*(0.024357719)*((0.022)*(0.022) + (0.0325)*(0.0325))}" iyz="0" izz="${(1/12)*(0.024357719)*((0.0325)*(0.0325) + (0.045)*(0.045))}"/>
      </inertial>
      <visual>
        <origin xyz="0 0 0" rpy="0 0 0"  />
        <geometry>
          <!--box size="0.045 0.022 0.0325" /-->
          <mesh filename="${prefix_stl}/tibia_l.STL"  scale="1 1 1"/>
        </geometry>
        <material name="Grey">
          <color rgba="0.20 0.20 0.20 1.0"/>
        </material>
      </visual>
      <collision>
        <origin xyz="0 0 0" rpy="0 0 0"  />
        <geometry>
          <mesh filename="${prefix_stl}/tibia_l_coll.STL"  scale="1 1 1"/>
        </geometry>
      </collision>
    </link>

    <joint name="j_c1_${suffix}" type="revolute">
      <parent link="MP_BODY"/>
      <child link="c1_${suffix}"/>
      <origin xyz="${xyz}" rpy="${rpy}" />
      <axis xyz="1 0 0" />
      <limit effort="2.8" velocity="5.6548668" lower="-2.6179939" upper="2.6179939" />
    </joint>

    <joint name="j_c2_${suffix}" type="fixed">
      <parent link="c1_${suffix}"/>
      <child link="c2_${suffix}"/>
      <origin xyz="0 -0.054 0" rpy="0 1.5704 3.14159" />
    </joint>

    <joint name="j_thigh_${suffix}" type="revolute">
      <parent link="c2_${suffix}"/>
      <child link="thigh_${suffix}"/>
      <origin xyz="0 0 0" rpy=" 0 3.14159 3.14159" />
      <axis xyz="1 0 0" />
      <limit effort="2.8" velocity="5.6548668" lower="-2.6179939" upper="2.6179939" />
    </joint>

    <joint name="j_tibia_${suffix}" type="revolute">
      <parent link="thigh_${suffix}"/>
      <child link="tibia_${suffix}"/>
      <origin xyz="0 ${thigh_offset_y} ${thigh_offset_z}" rpy="-1.5707 0 3.14159" />
      <axis xyz="1 0 0" />
      <limit effort="2.8" velocity="5.6548668" lower="-2.6179939" upper="2.6179939" />
    </joint>


  </xacro:macro>





</robot>
